<?xml version="1.0"?>
<!-- This URDF was automatically created by SolidWorks to URDF Exporter! Originally created by Stephen Brawner (brawner@gmail.com) 
     Commit Version: 1.6.0-1-g15f4949  Build Version: 1.6.7594.29634
     For more information, please see http://wiki.ros.org/sw_urdf_exporter -->

<robot xmlns:xacro="http://www.ros.org/wiki/xacro" >

	<material name="red"> 
		<color rgba="0.69412 0.098039 0.098039 1" />
      	</material>
      	
      	<material name="white">
        	<color rgba="0.79216 0.81961 0.93333 1" />
      	</material>
      	
      	<material name="black">
		<color rgba="0.25098 0.25098 0.25098 1" />
      	</material>
      	

	<!--BASE LINK-->
	<link name="base_footprint">
	
  	</link>
	
	<joint name="base_joint" type="fixed">
		<parent link="base_footprint" />
    		<child link="base_link" />
    		<origin xyz="0 0 0.22579" rpy="0 -0.150640 0" />
  	</joint>
	
	<link name="base_link">
		<visual>
      			<origin xyz="0 0 0" rpy="0 0 0" />
      			<geometry>
        			<mesh filename="file://$(find chimuelo_description)/meshes/base_link.STL" />
    			</geometry>
      			<material name="red"/>
    		</visual>
    		
    		<collision>
      			<origin xyz="0 0 0.09255" rpy="0 0.150640 0" />
      			<geometry>
       			<box size="0.4806 0.316 0.35323" />
     			</geometry>
    		</collision>
    		
		<inertial>
      			<origin xyz="-0.019376 0.0012573 0.047484" rpy="0 0 0" />
      			<mass value="9.3362" />
      			<inertia
        			ixx="0.10996"
        			ixy="-0.00014648"
        			ixz="0.015965"
        			iyy="0.1362"
        			iyz="0.00018862"
        			izz="0.18143" />
    		</inertial>
    		
	</link>
	
	<!--SUPPORT RIGHT LINK-->
	<joint name="support_right_joint" type="fixed">
    		<parent link="base_link" />
    		<child link="support_right_link" />
    		<origin xyz="0.020526 -0.15792 0.071163" rpy="1.5708 0 1.5708" />
    		<axis xyz="0 0 0" />
  	</joint>
  
	<link name="support_right_link">
		<visual>
      			<origin xyz="0 0 0" rpy="0 0 0" />
      			<geometry>
        			<mesh filename="file://$(find chimuelo_description)/meshes/support_right_link.STL" />
      			</geometry>
      			<material name="white" />
    		</visual>
    		
    		<collision>
      			<origin xyz="0 0 0" rpy="0 0 0" />
      			<geometry>
        			<mesh filename="file://$(find chimuelo_description)/meshes/support_right_link.STL" />
      			</geometry>
    		</collision>
    		
    		<inertial>
      			<origin xyz="0.004811 -0.076737 0.049761" rpy="0 0 0" />
      			<mass value="0.35361" />
      			<inertia
        			ixx="0.0028314"
        			ixy="-8.4377E-06"
        			ixz="5.4716E-06"
        			iyy="0.00092025"
        			iyz="0.0011281"
        			izz="0.0019284" />
    		</inertial>
	</link>
	
	<!--SUPPORT LEFT LINK-->
	<joint name="support_left_joint" type="fixed">
    		<parent link="base_link" />
    		<child link="support_left_link" />
    		<origin xyz="0.020526 0.16108 0.071163" rpy="1.5708 0 1.5708" />
    		<axis xyz="0 0 0" />
  	</joint>
  
	<link name="support_left_link">
		<visual>
      			<origin xyz="0 0 0" rpy="0 0 0" />
      			<geometry>
        			<mesh filename="file://$(find chimuelo_description)/meshes/support_left_link.STL" />
      			</geometry>
      			<material name="white" />
    		</visual>
    		
    		<collision>
      			<origin xyz="0 0 0" rpy="0 0 0" />
      			<geometry>
        			<mesh filename="file://$(find chimuelo_description)/meshes/support_left_link.STL" />
      			</geometry>
    		</collision>
    		
    		<inertial>
      			<origin xyz="-0.007811 -0.076737 0.049761" rpy="0 0 0" />
      			<mass value="0.35361" />
      			<inertia
        			ixx="0.0028314"
        			ixy="8.4377E-06"
        			ixz="-5.4716E-06"
        			iyy="0.00092025"
        			iyz="0.0011281"
        			izz="0.0019284" />
    		</inertial>
	</link>
	
	<!--WHEEL LINK (RIGHT)-->
	<joint name="front_right_joint" type="continuous">
		<parent link="base_link" />
    		<child link="front_right_wheel" />
    		<origin xyz="0.15956 -0.22452 -0.14324" rpy="0.150640 0 1.5708" />
    		<axis xyz="1 0 0" />
  	</joint>
  	
  	<link name="front_right_wheel">
  		<visual>
      			<origin xyz="0 0 0" rpy="0 0 3.1416" />
      			<geometry>
        			<mesh filename="file://$(find chimuelo_description)/meshes/front_right_wheel.STL" />
      			</geometry>
      			<material name="black"/>
    		</visual>
    		
    		<collision>
      			<origin xyz="0.027 0 0" rpy="0 1.5708 0" />
      			<geometry>
        			<cylinder length="0.054" radius="0.079375" />
      			</geometry>
    		</collision>
    		
   		<inertial>
      			<origin xyz="-0.030145 7.2299E-06 -7.774E-07" rpy="0 0 0" />
      			<mass value="0.95802" />
      			<inertia
        			ixx="0.0027027"
        			ixy="3.8106E-07"
        			ixz="-4.0985E-08"
        			iyy="0.0015854"
        			iyz="-3.6463E-09"
        			izz="0.0015854" />
    		</inertial>
    		
  	</link>
  	
  	<!--WHEEL LINK (LEFT)-->
  	<joint name="front_left_joint" type="continuous">
  		<parent link="base_link" />
    		<child link="front_left_wheel" />
    		<origin xyz="0.15956 0.11368 -0.14324" rpy="0.150640 0 1.5708" />
		<axis xyz="1 0 0" />
  	</joint>
  	
  	<link name="front_left_wheel">
  		<visual>
      			<origin xyz="0 0 0" rpy="0 0 0" />
      			<geometry>
        			<mesh filename="file://$(find chimuelo_description)//meshes/front_left_wheel.STL" />
      			</geometry>
      			<material name="black"/>
        	</visual>
    		
    		<collision>
      			<origin xyz="0.081 0 0" rpy="0 1.5708 0" />
      			<geometry>
        			<cylinder length="0.054" radius="0.079375" />
      			</geometry>
    		</collision>
    		
    		<inertial>
      			<origin xyz="0.080855 -3.7512E-06 6.2293E-06" rpy="0 0 0" />
      			<mass value="0.95802" />
      			<inertia
        			ixx="0.0027027"
        			ixy="-1.9771E-07"
        			ixz="3.2833E-07"
        			iyy="0.0015854"
        			iyz="-1.5204E-08"
        			izz="0.0015854" />
    		</inertial>
    		
  	</link>
  	
  	<!--CASTER WHEEL LINK (RIGHT)-->
  	<joint name="rear_right_joint1" type="continuous">
  		<parent link="base_link" />
    		<child link="rear_right_link" />
    		<origin xyz="-0.12756 -0.076921 -0.14918" rpy="1.5688 0.13961 -0.014686" />
    		<axis xyz="0 1 0" />
  	</joint>
  	
  	<link name="rear_right_link">
  		<visual>
      			<origin xyz="0 0 0" rpy="0 0 0" />
      			<geometry>
        			<mesh filename="file://$(find chimuelo_description)/meshes/rear_right_link.STL" />
      			</geometry>
      			<material name="white"/>
    		</visual>
    		
    		<collision>
      			<origin xyz="0 0.07459 0" rpy="1.5708 0 0" />
      			<geometry>
       	 		<box size="0.107 0.086 0.025" />
      			</geometry>
    		</collision>
    		
    		<inertial>
      			<origin xyz="-0.013975 0.054321 9.9024E-05" rpy="0 0 0" />
      			<mass value="0.053734" />
      			<inertia
       			ixx="2.524E-05"
       			ixy="-1.6585E-06"
        			ixz="9.9779E-08"
        			iyy="2.9055E-05"
        			iyz="2.0355E-07"
        			izz="2.0458E-05" />
    		</inertial>
    		
  	</link>
  	
  	<joint name="rear_right_joint2" type="continuous">
  		<parent link="rear_right_link" />
    		<child link="rear_right_wheel" />
    		<origin xyz="-0.03659 0.014924 -0.0015141" rpy="2.894 -1.5708 0" />
    		<axis xyz="1 0 0" />
  	</joint>
  	
  	<link name="rear_right_wheel">
  		<visual>
      			<origin xyz="0 0 0" rpy="0 0 0" />
      			<geometry>
        			<mesh filename="file://$(find chimuelo_description)/meshes/rear_right_wheel.STL"/>
      			</geometry>
      			<material name="black"/>
    		</visual>
    		
    		<collision>
      			<origin xyz="0 0 0" rpy="0 -1.5708 0"/>
      			<geometry>
        			<cylinder length="0.032" radius="0.045"/>
      			</geometry>
    		</collision>
    		
    		<inertial>
      			<origin xyz="0.0014035 7.5454E-12 1.17E-06" rpy="0 0 0" />
      			<mass value="0.2056" />
      			<inertia
        			ixx="0.00020145"
        			ixy="-4.2403E-14"
       			ixz="-5.6953E-14"
       			iyy="0.00011972"
        			iyz="5.3531E-16"
        			izz="0.00011972" />
    		</inertial>
    		
  	</link>
  	
  	<!--CASTER WHEEL LINK (LEFT)-->
  	<joint name="rear_left_joint1" type="continuous">
  		<parent link="base_link" />
    		<child link="rear_left_link" />
    		<origin xyz="-0.12756 0.077079 -0.14918" rpy="1.5688 0.13961 -0.014686" />
    		<axis xyz="0 1 0" />
  	</joint>
  	
  	<link name="rear_left_link">
  		<visual>
    			<origin xyz="0 0 0" rpy="0 0 0" />
      			<geometry>
        			<mesh filename="file://$(find chimuelo_description)/meshes/rear_left_link.STL" />
      			</geometry>
      			<material name="white"/>
    		</visual>
    		
    		<collision>
      			<origin xyz="0 0.07459 0" rpy="1.5708 0 0" />
      			<geometry>
        			<box size="0.107 0.086 0.025" />
      			</geometry>
    		</collision>
    		
    		<inertial>
      			<origin xyz="-0.013975 0.054321 9.9024E-05" rpy="0 0 0" />
      			<mass value="0.053734" />
      			<inertia
        			ixx="2.524E-05"
        			ixy="-1.6585E-06"
        			ixz="9.9779E-08"
        			iyy="2.9055E-05"
        			iyz="2.0355E-07"
        			izz="2.0458E-05" />
    		</inertial>
    		
  	</link>
  	
  	<joint name="rear_left_joint2" type="continuous">
  		<parent link="rear_left_link" />
    		<child link="rear_left_wheel" />
    		<origin xyz="-0.03659 0.014924 -0.0015141" rpy="2.894 -1.5708 0" />
    		<axis xyz="1 0 0" />
  	</joint>
  	
  	<link name="rear_left_wheel">
  		<visual>
      			<origin xyz="0 0 0" rpy="0 0 0" />
      			<geometry>
        			<mesh filename="file://$(find chimuelo_description)/meshes/rear_left_wheel.STL" />
      			</geometry>
      			<material name="black"/>
    		</visual>
    		
    		<collision>
      			<origin xyz="0 0 0" rpy="0 -1.5708 0" />
      			<geometry>
        			<cylinder length="0.032" radius="0.045" />
      			</geometry>
    		</collision>
    		
    		<inertial>
      			<origin xyz="0.0014035 7.5453E-12 1.17E-06" rpy="0 0 0" />
      			<mass value="0.2056" />
      			<inertia
        			ixx="0.00020145"
        			ixy="-4.2403E-14"
        			ixz="-5.6953E-14"
        			iyy="0.00011972"
        			iyz="5.3532E-16"
        			izz="0.00011972" />
    		</inertial>
    			
  	</link>
  
 	<gazebo reference="base_link">
		<material>Gazebo/Red</material>
  	</gazebo>
  	
	<gazebo reference="support_right_link">
		<material>Gazebo/White</material>
	</gazebo>
  	
 	<gazebo reference="support_left_link">
		<material>Gazebo/White</material>
	</gazebo>
  	
  	<gazebo reference="front_right_wheel">
		<material>Gazebo/Black</material>
	</gazebo>
  	
  	<gazebo reference="front_left_wheel">
		<material>Gazebo/Black</material>
	</gazebo>
  	
  	<gazebo reference="rear_right_link">
		<material>Gazebo/White</material>
	</gazebo>
  	
  	<gazebo reference="rear_right_wheel">
		<material>Gazebo/Black</material>
	</gazebo>
  	
  	<gazebo reference="rear_left_link">
		<material>Gazebo/White</material>
	</gazebo>
  	
  	<gazebo reference="rear_left_wheel">
		<material>Gazebo/Black</material>
	</gazebo>

</robot>